<?xml version="1.0" encoding="UTF-8"?>
<!-- Generated by org.testng.reporters.JUnitReportReporter -->
<testsuite skipped="3" hostname="LAPTOP-HK26NAV8" name="Admin_Module.create_classroomPOMTest_1" tests="5" failures="1" timestamp="2023-01-12T17:42:13 IST" time="5.127" errors="0">
  <testcase name="excuteConfig" time="0.898" classname="Admin_Module.create_classroomPOMTest_1">
    <skipped/>
  </testcase> <!-- excuteConfig -->
  <system-out>
    <![CDATA[excuteConfig-----method started excuted
method got skipped]]>
  </system-out>
  <testcase name="excuteConfig" time="1.675" classname="Admin_Module.create_classroomPOMTest_1">
    <skipped/>
  </testcase> <!-- excuteConfig -->
  <system-out>
    <![CDATA[excuteConfig-----method started excuted
method got skipped]]>
  </system-out>
  <testcase name="excuteConfig" time="0.981" classname="Admin_Module.create_classroomPOMTest_1">
    <skipped/>
  </testcase> <!-- excuteConfig -->
  <system-out>
    <![CDATA[excuteConfig-----method started excuted
method got skipped]]>
  </system-out>
  <testcase name="sample1" time="0.675" classname="Admin_Module.create_classroomPOMTest_1"/>
  <system-out>
    <![CDATA[sample1-----method started excuted
method got excuted successs]]>
  </system-out>
  <testcase name="excuteConfig" time="0.898" classname="Admin_Module.create_classroomPOMTest_1">
    <failure type="java.lang.AssertionError" message="null">
      <![CDATA[java.lang.AssertionError: null
at org.testng.Assert.fail(Assert.java:99)
at org.testng.Assert.fail(Assert.java:106)
at Admin_Module.create_classroomPOMTest_1.excuteConfig(create_classroomPOMTest_1.java:28)
at sun.reflect.NativeMethodAccessorImpl.invoke0(Native Method)
at sun.reflect.NativeMethodAccessorImpl.invoke(Unknown Source)
at sun.reflect.DelegatingMethodAccessorImpl.invoke(Unknown Source)
at java.lang.reflect.Method.invoke(Unknown Source)
at org.testng.internal.MethodInvocationHelper.invokeMethod(MethodInvocationHelper.java:133)
at org.testng.internal.TestInvoker.invokeMethod(TestInvoker.java:598)
at org.testng.internal.TestInvoker.retryFailed(TestInvoker.java:213)
at org.testng.internal.MethodRunner.runInSequence(MethodRunner.java:58)
at org.testng.internal.TestInvoker$MethodInvocationAgent.invoke(TestInvoker.java:824)
at org.testng.internal.TestInvoker.invokeTestMethods(TestInvoker.java:146)
at org.testng.internal.TestMethodWorker.invokeTestMethods(TestMethodWorker.java:146)
at org.testng.internal.TestMethodWorker.run(TestMethodWorker.java:128)
at java.util.ArrayList.forEach(Unknown Source)
at org.testng.TestRunner.privateRun(TestRunner.java:794)
at org.testng.TestRunner.run(TestRunner.java:596)
at org.testng.SuiteRunner.runTest(SuiteRunner.java:377)
at org.testng.SuiteRunner.access$000(SuiteRunner.java:28)
at org.testng.SuiteRunner$SuiteWorker.run(SuiteRunner.java:418)
at org.testng.internal.thread.ThreadUtil.lambda$execute$0(ThreadUtil.java:64)
at java.util.concurrent.FutureTask.run(Unknown Source)
at java.util.concurrent.ThreadPoolExecutor.runWorker(Unknown Source)
at java.util.concurrent.ThreadPoolExecutor$Worker.run(Unknown Source)
at java.lang.Thread.run(Unknown Source)
]]>
    </failure>
  </testcase> <!-- excuteConfig -->
  <system-out>
    <![CDATA[excuteConfig-----method started excuted]]>
  </system-out>
</testsuite> <!-- Admin_Module.create_classroomPOMTest_1 -->
